curated
curated
curated
curated
curated
curated
curated
curated
curated
curated
curated
curated
curated
curated
curated
curated
curated
Traceback (most recent call last):
  File "/media/robin/Documents/PersonalWorks/ibas_project/ibas-chatbot/final_curator.py", line 380, in <module>
    main()
  File "/media/robin/Documents/PersonalWorks/ibas_project/ibas-chatbot/final_curator.py", line 373, in main
    df = pd.read_excel("/home/tanjim/workstation/ibas-project/source/final_dataset.xlsx")
  File "/home/robin/anaconda3/lib/python3.10/site-packages/pandas/util/_decorators.py", line 211, in wrapper
    return func(*args, **kwargs)
  File "/home/robin/anaconda3/lib/python3.10/site-packages/pandas/util/_decorators.py", line 331, in wrapper
    return func(*args, **kwargs)
  File "/home/robin/anaconda3/lib/python3.10/site-packages/pandas/io/excel/_base.py", line 482, in read_excel
    io = ExcelFile(io, storage_options=storage_options, engine=engine)
  File "/home/robin/anaconda3/lib/python3.10/site-packages/pandas/io/excel/_base.py", line 1652, in __init__
    ext = inspect_excel_format(
  File "/home/robin/anaconda3/lib/python3.10/site-packages/pandas/io/excel/_base.py", line 1525, in inspect_excel_format
    with get_handle(
  File "/home/robin/anaconda3/lib/python3.10/site-packages/pandas/io/common.py", line 865, in get_handle
    handle = open(handle, ioargs.mode)
FileNotFoundError: [Errno 2] No such file or directory: '/home/tanjim/workstation/ibas-project/source/final_dataset.xlsx'
Traceback (most recent call last):
  File "/home/robin/anaconda3/lib/python3.10/site-packages/pandas/core/indexes/base.py", line 3802, in get_loc
    return self._engine.get_loc(casted_key)
  File "pandas/_libs/index.pyx", line 138, in pandas._libs.index.IndexEngine.get_loc
  File "pandas/_libs/index.pyx", line 165, in pandas._libs.index.IndexEngine.get_loc
  File "pandas/_libs/hashtable_class_helper.pxi", line 5745, in pandas._libs.hashtable.PyObjectHashTable.get_item
  File "pandas/_libs/hashtable_class_helper.pxi", line 5753, in pandas._libs.hashtable.PyObjectHashTable.get_item
KeyError: 'Questions'

The above exception was the direct cause of the following exception:

Traceback (most recent call last):
  File "/media/robin/Documents/PersonalWorks/ibas_project/ibas-chatbot/final_curator.py", line 381, in <module>
    main()
  File "/media/robin/Documents/PersonalWorks/ibas_project/ibas-chatbot/final_curator.py", line 376, in main
    create_new_files(df)
  File "/media/robin/Documents/PersonalWorks/ibas_project/ibas-chatbot/final_curator.py", line 274, in create_new_files
    ques = row["Questions"].strip("'").strip('"').strip()
  File "/home/robin/anaconda3/lib/python3.10/site-packages/pandas/core/series.py", line 981, in __getitem__
    return self._get_value(key)
  File "/home/robin/anaconda3/lib/python3.10/site-packages/pandas/core/series.py", line 1089, in _get_value
    loc = self.index.get_loc(label)
  File "/home/robin/anaconda3/lib/python3.10/site-packages/pandas/core/indexes/base.py", line 3804, in get_loc
    raise KeyError(key) from err
KeyError: 'Questions'
curated
curated
curated
curated
curated
curated
curated
curated
curated
curated
curated
curated
curated
curated
curated
curated
